Traceback (most recent call last):
  File "C:\Users\GLENDY\AppData\Local\Programs\Python\Python311\Lib\site-packages\jupyter_cache\executors\utils.py", line 58, in single_nb_execution
    executenb(
  File "C:\Users\GLENDY\AppData\Local\Programs\Python\Python311\Lib\site-packages\nbclient\client.py", line 1314, in execute
    return NotebookClient(nb=nb, resources=resources, km=km, **kwargs).execute()
           ^^^^^^^^^^^^^^^^^^^^^^^^^^^^^^^^^^^^^^^^^^^^^^^^^^^^^^^^^^^^^^^^^^^^^
  File "C:\Users\GLENDY\AppData\Roaming\Python\Python311\site-packages\jupyter_core\utils\__init__.py", line 173, in wrapped
    return loop.run_until_complete(inner)
           ^^^^^^^^^^^^^^^^^^^^^^^^^^^^^^
  File "C:\Users\GLENDY\AppData\Local\Programs\Python\Python311\Lib\asyncio\base_events.py", line 653, in run_until_complete
    return future.result()
           ^^^^^^^^^^^^^^^
  File "C:\Users\GLENDY\AppData\Local\Programs\Python\Python311\Lib\site-packages\nbclient\client.py", line 709, in async_execute
    await self.async_execute_cell(
  File "C:\Users\GLENDY\AppData\Local\Programs\Python\Python311\Lib\site-packages\nbclient\client.py", line 1062, in async_execute_cell
    await self._check_raise_for_error(cell, cell_index, exec_reply)
  File "C:\Users\GLENDY\AppData\Local\Programs\Python\Python311\Lib\site-packages\nbclient\client.py", line 918, in _check_raise_for_error
    raise CellExecutionError.from_cell_and_msg(cell, exec_reply_content)
nbclient.exceptions.CellExecutionError: An error occurred while executing the following cell:
------------------
from ucimlrepo import fetch_ucirepo 
  
# fetch dataset 
breast_cancer_wisconsin_original = fetch_ucirepo(id=15) 
  
# data (as pandas dataframes) 
data = breast_cancer_wisconsin_original.data.original 
  # menyimpan hasil komputasi ke dalam csv
data.to_csv("breast_cancer.csv", index=True)
print(data.info()) #untuk menampilkan info fitur-fitur yang ada di tabel

print(data.head()) #untuk menampilkan 5 baris pertama
------------------


[1;31m---------------------------------------------------------------------------[0m
[1;31mModuleNotFoundError[0m                       Traceback (most recent call last)
Cell [1;32mIn[2], line 1[0m
[1;32m----> 1[0m [38;5;28;01mfrom[39;00m [38;5;21;01mucimlrepo[39;00m [38;5;28;01mimport[39;00m fetch_ucirepo 
[0;32m      3[0m [38;5;66;03m# fetch dataset [39;00m
[0;32m      4[0m breast_cancer_wisconsin_original [38;5;241m=[39m fetch_ucirepo([38;5;28mid[39m[38;5;241m=[39m[38;5;241m15[39m) 

[1;31mModuleNotFoundError[0m: No module named 'ucimlrepo'

